Workbook

Sheet Index
A1: Performance Foodservice - Master Item List
A2: The Country Club at Old Hawthorne | Combined from 13 shelf-to-sheet and purchase-history exports (generated 09/06/2026)
A4: How this list was built
A5: 1. Two of the uploaded files were byte-for-byte identical (Seafood Stocked). The copy was dropped.
A6: 2. Every item is de-duplicated by Product Number. One row per product number, no matter how many lists it appeared on.
A7: 3. When the same product number carried different prices across lists, this sheet shows the HIGHEST price found,
A8: so a plate never gets under-costed. Column I flags any item where prices disagreed between files.
A9: 4. Column J lists every source sheet the item was found on, so you can trace it back.
A10: 5. Categories are derived from the product description (the vendor files have no category field).
A11: Items are then sorted by Item Group inside each category so like items sit together.
A12: 6. Prices are as of the 09/05-09/06/2026 exports. Performance's own disclaimer: prices subject to change.
A15: Category | B15: Items | C15: Priced Items | D15: Total of Listed Prices
A16: Beef | B16: 182 | C16: =COUNT(Beef!G5:G187) -> 182 | D16: =SUM(Beef!G5:G187) -> 4386.8404
A17: Pork | B17: 70 | C17: =COUNT(Pork!G5:G87) -> 70 | D17: =SUM(Pork!G5:G87) -> 2856.1416
A18: Poultry | B18: 32 | C18: =COUNT(Poultry!G5:G40) -> 32 | D18: =SUM(Poultry!G5:G40) -> 1456.1905
A19: Other Meat | B19: 11 | C19: =COUNT('Other Meat'!G5:G21) -> 11 | D19: =SUM('Other Meat'!G5:G21) -> 775.1313
A20: Seafood | B20: 176 | C20: =COUNT(Seafood!G5:G215) -> 176 | D20: =SUM(Seafood!G5:G215) -> 22043.78
A21: Dairy & Eggs | B21: 83 | C21: =COUNT('Dairy & Eggs'!G5:G98) -> 83 | D21: =SUM('Dairy & Eggs'!G5:G98) -> 4015.455
A22: Produce | B22: 226 | C22: =COUNT(Produce!G5:G305) -> 226 | D22: =SUM(Produce!G5:G305) -> 9402.69
A23: Bakery & Bread | B23: 82 | C23: =COUNT('Bakery & Bread'!G5:G112) -> 82 | D23: =SUM('Bakery & Bread'!G5:G112) -> 3879.85
A24: Frozen & Prepared Foods | B24: 40 | C24: =COUNT('Frozen & Prepared Foods'!G5:G58) -> 40 | D24: =SUM('Frozen & Prepared Foods'!G5:G58) -> 2702.68
A25: Sauces, Dressings & Condiments | B25: 76 | C25: =COUNT('Sauces, Dressings & Condiments'!G5:G94) -> 76 | D25: =SUM('Sauces, Dressings & Condiments'!G5:G94) -> 4621.38
A26: Oils & Vinegars | B26: 22 | C26: =COUNT('Oils & Vinegars'!G5:G29) -> 22 | D26: =SUM('Oils & Vinegars'!G5:G29) -> 1633.29
A27: Spices & Seasonings | B27: 45 | C27: =COUNT('Spices & Seasonings'!G5:G71) -> 45 | D27: =SUM('Spices & Seasonings'!G5:G71) -> 1938.48
A28: Canned & Jarred | B28: 33 | C28: =COUNT('Canned & Jarred'!G5:G49) -> 32 | D28: =SUM('Canned & Jarred'!G5:G49) -> 1805.83
A29: Dry Goods & Baking | B29: 63 | C29: =COUNT('Dry Goods & Baking'!G5:G94) -> 63 | D29: =SUM('Dry Goods & Baking'!G5:G94) -> 3532.5
A30: Beverages | B30: 49 | C30: =COUNT(Beverages!G5:G65) -> 49 | D30: =SUM(Beverages!G5:G65) -> 2771.49
A31: Snacks, Candy & Desserts | B31: 74 | C31: =COUNT('Snacks, Candy & Desserts'!G5:G101) -> 74 | D31: =SUM('Snacks, Candy & Desserts'!G5:G101) -> 4332.81
A32: Disposables & Packaging | B32: 76 | C32: =COUNT('Disposables & Packaging'!G5:G111) -> 76 | D32: =SUM('Disposables & Packaging'!G5:G111) -> 5515.31
A33: Chemicals & Cleaning | B33: 31 | C33: =COUNT('Chemicals & Cleaning'!G5:G50) -> 31 | D33: =SUM('Chemicals & Cleaning'!G5:G50) -> 3066.42
A34: Equipment & Misc | B34: 5 | C34: =COUNT('Equipment & Misc'!G5:G13) -> 5 | D34: =SUM('Equipment & Misc'!G5:G13) -> 134.43
A35: House / Custom Items | B35: 5 | C35: =COUNT('House - Custom Items'!G5:G13) -> 0 | D35: =SUM('House - Custom Items'!G5:G13) -> 0
A36: TOTAL | B36: =SUM(B16:B35) -> 1381 | C36: =SUM(C16:C35) -> 1375 | D36: =SUM(D16:D35) -> 80870.698

Sheet Beef
A1: Beef
A2: Prices as of 09/06/2026 export. Where a product appeared on more than one list with different prices, the highest is shown.
A4: Item Group | B4: Product Description | C4: Brand | D4: Product # | E4: Pack Size | F4: UOM | G4: Price | H4: Price Basis | I4: Price Varies? | J4: Found On These Lists
A5: BEEF
A6: BEEF | B6: BEEF ANGUS BACK RIB CHOICE | C6: RUTH FAMILY CHOICE | D6: 882612 | E6: 14/4 LB | F6: CS | G6: 6.1199 | H6: per lb | J6: Ruth Family Farms & Ranch to Table
A7: BEEF | B7: BEEF ANGUS BACK RIBS PRIME 124 | C7: RUTH FAMILY PRIME | D7: 874241 | E7: 14/4 LB | F7: CS | G7: 4.8599 | H7: per lb | J7: Ruth Family Farms & Ranch to Table
A8: BEEF | B8: BEEF ANGUS BOTTOM SIRLOIN CHOICE 185A | C8: RUTH FAMILY CHOICE | D8: 874231 | E8: 12/4 LB | F8: CS | G8: 12.5699 | H8: per lb | J8: Ruth Family Farms & Ranch to Table
A9: BEEF | B9: BEEF ANGUS BOTTOM SIRLOIN PRIME 185A | C9: RUTH FAMILY PRIME | D9: 874384 | E9: 12/4 LB | F9: CS | G9: 15.9499 | H9: per lb | J9: Ruth Family Farms & Ranch to Table
A10: BEEF | B10: BEEF ANGUS BRISKET BONELESS PRIME DECKLE OFF | C10: RUTH FAMILY PRIME | D10: 886097 | E10: 5/12 LB | F10: CS | G10: 9.8699 | H10: per lb | J10: Ruth Family Farms & Ranch to Table
A11: BEEF | B11: BEEF ANGUS BRISKET CHOICE BONELESS DECKLE OFF | C11: RUTH FAMILY CHOICE | D11: 882504 | E11: 5/12 LB | F11: CS | G11: 7.2699 | H11: per lb | J11: Ruth Family Farms & Ranch to Table
A12: BEEF | B12: BEEF ANGUS BRISKET FLAT | C12: CAB | D12: 953805 | E12: 8/6-7 LB | F12: CS | G12: 9.2067 | H12: per lb | I12: YES | J12: Inventory Plink, Purchase History, S2S Walkin, TCOH S2S, s2s House & Banquets
A13: BEEF | B13: BEEF ANGUS BRISKET FLAT | C13: CAB | D13: 398938 | E13: 8/6-7 LB | F13: CS | G13: 8.7599 | H13: per lb | J13: s2s House & Banquets
A14: BEEF | B14: BEEF ANGUS CHUCK FLAP BONELESS EIGHT PIECES PER PACK | C14: CAB | D14: 439020 | E14: 6/12.5 LB | F14: CS | G14: 13.8144 | H14: per lb | J14: S2S Walkin
A15: BEEF | B15: BEEF ANGUS CHUCK GROUND FINE 80/20 | C15: PERFORMANCE CAB | D15: 602019 | E15: 4/5 LB | F15: CS | G15: 135.31 | H15: per case | J15: Inventory Plink, TCOH S2S
A16: BEEF | B16: BEEF ANGUS CHUCK GROUND FINE 80/20 PREMIUM CERTIFIED_ANGUS_BEEF | C16: CAB | D16: 41341 | E16: 6/10 LB | F16: CS | G16: 5.1561 | H16: per lb | I16: YES | J16: DOWNSTAIRS FREEZER S2S, Inventory Plink, Purchase History, S2S Walkin, S2S Walkin Freezer, TCOH S2S, s2s House & Banquets
A17: BEEF | B17: BEEF ANGUS CHUCK ROLL NECK OFF | C17: CAB | D17: 68332 | E17: 3/23 LB | F17: CS | G17: 6.9121 | H17: per lb | J17: Purchase History
A18: BEEF | B18: BEEF ANGUS CHUCK ROLL NECK OFF CHOICE | C18: RUTH FAMILY CHOICE | D18: 882494 | E18: 3/20 LB | F18: CS | G18: 6.9499 | H18: per lb | J18: Ruth Family Farms & Ranch to Table
A19: BEEF | B19: BEEF ANGUS CHUCK ROLL NECK OFF PRIME | C19: RUTH FAMILY PRIME | D19: 886030 | E19: 3/20 LB | F19: CS | G19: 9.1099 | H19: per lb | J19: Ruth Family Farms & Ranch to Table
A20: BEEF | B20: BEEF ANGUS CHUCK ROLL NECK OFF PRIME CERTIFIED_ANGUS_BEEF | C20: CAB | D20: 875216 | E20: 3/20 LB | F20: CS | G20: 5.5099 | H20: per lb | J20: Ruth Family Farms & Ranch to Table
A21: BEEF | B21: BEEF ANGUS CHUCK SHORT RIB ANTIBIOTIC_FREE PRIME BONELESS | C21: MIDDENDORF | D21: 1013576 | E21: 14/12 OZ | F21: CS | G21: 20.1099 | H21: per lb | J21: Purchase History
A22: BEEF | B22: BEEF ANGUS CHUCK SHORT RIB CHOICE 130 | C22: RUTH FAMILY CHOICE | D22: 874158 | E22: 12/5 LB | F22: CS | G22: 8.5099 | H22: per lb | J22: Ruth Family Farms & Ranch to Table
A23: BEEF | B23: BEEF ANGUS CHUCK SHORT RIB PRIME 130 | C23: RUTH FAMILY PRIME | D23: 874248 | E23: 12/5 LB | F23: CS | G23: 7.4099 | H23: per lb | J23: Ruth Family Farms & Ranch to Table
A24: BEEF | B24: BEEF ANGUS CHUCK SHOULDER CLOD CHOICE | C24: RUTH FAMILY CHOICE | D24: 882429 | E24: 3/20 LB | F24: CS | G24: 5.9599 | H24: per lb | J24: Ruth Family Farms & Ranch to Table
A25: BEEF | B25: BEEF ANGUS CHUCK SHOULDER CLOD PRIME CERTIFIED_ANGUS_BEEF | C25: CAB | D25: 875187 | E25: 3/20 LB | F25: CS | G25: 4.7399 | H25: per lb | J25: Ruth Family Farms & Ranch to Table, S2S Walkin
A26: BEEF | B26: BEEF ANGUS CHUCK SHOULDER CLOD TRIMMED PRIME | C26: RUTH FAMILY PRIME | D26: 885356 | E26: 3/20 LB | F26: CS | G26: 7.4099 | H26: per lb | J26: Ruth Family Farms & Ranch to Table
A27: BEEF | B27: BEEF ANGUS CHUCK SHOULDER TENDER CHOICE | C27: RUTH FAMILY CHOICE | D27: 882443 | E27: 8/5 LB | F27: CS | G27: 7.1899 | H27: per lb | J27: Ruth Family Farms & Ranch to Table
A28: BEEF | B28: BEEF ANGUS CHUCK SHOULDER TENDER PRIME CERTIFIED_ANGUS_BEEF | C28: CAB | D28: 875215 | E28: 8/5 LB | F28: CS | G28: 7.1799 | H28: per lb | J28: Ruth Family Farms & Ranch to Table
... A56: BEEF | B56: BEEF ANGUS PATTY 4/1 GROUND PUCK FOUR PER VACUUM-PACKED | C56: PERFORMANCE CAB | D56: 590333 | E56: 40/4 OZ | F56: CS | G56: 5.9946 | H56: per lb | J56: Purchase History
A57: BEEF | B57: BEEF ANGUS PATTY 4/1 PUB FULLY-COOKED FROZEN | C57: CAB | D57: 75685 | E57: 40/4 OZ | F57: CS | G57: 139.66 | H57: per case | I57: YES | J57: Inventory Plink, Purchase History, S2S Walkin Freezer, TCOH S2S, s2s House & Banquets
A58: BEEF | B58: BEEF ANGUS PATTY 8/1 GROUND PUCK CHUCK | C58: PERFORMANCE CAB | D58: 601728 | E58: 80/2 OZ | F58: CS | G58: 67.19 | H58: per case | J58: Inventory Plink
A59: BEEF | B59: BEEF ANGUS PATTY CHUCK GROUND ROUND | C59: CAB_PFG CUSTOM MEATS | D59: 602225 | E59: 48/4 OZ | F59: CS | G59: 80.06 | H59: per case | I59: YES | J59: Inventory Plink, Purchase History, S2S Walkin, TCOH S2S, s2s House & Banquets
A60: BEEF | B60: BEEF ANGUS RIBEYE BONE-IN CHOICE 1103 | C60: PERFORMANCE CAB | D60: 351085 | E60: 8/22 OZ | F60: CS | G60: 21.7699 | H60: per lb | J60: Inventory Plink, TCOH S2S
A61: BEEF | B61: BEEF ANGUS RIBEYE BONELESS LIP-ON PRIME CERTIFIED_ANGUS_BEEF | C61: CAB | D61: 875153 | E61: 4/15 LB | F61: CS | G61: 23.977 | H61: per lb | J61: Ruth Family Farms & Ranch to Table
A62: BEEF | B62: BEEF ANGUS RIBEYE CAP CHOICE | C62: RUTH FAMILY CHOICE | D62: 882304 | E62: 16/4 LB | F62: CS | G62: 6.9899 | H62: per lb | J62: Ruth Family Farms & Ranch to Table
A63: BEEF | B63: BEEF ANGUS RIBEYE CAP PRIME CERTIFIED_ANGUS_BEEF | C63: CAB | D63: 875179 | E63: 16/4 LB | F63: CS | G63: 5.5899 | H63: per lb | J63: Ruth Family Farms & Ranch to Table
A64: BEEF | B64: BEEF ANGUS RIBEYE LIP-ON BONE-IN CHOICE | C64: RUTH FAMILY CHOICE | D64: 882270 | E64: 2/15 LB | F64: CS | G64: 23.0799 | H64: per lb | J64: Ruth Family Farms & Ranch to Table
A65: BEEF | B65: BEEF ANGUS RIBEYE LIP-ON BONE-IN PRIME | C65: RUTH FAMILY PRIME | D65: 885341 | E65: 2/15 LB | F65: CS | G65: 19.6799 | H65: per lb | J65: Ruth Family Farms & Ranch to Table
A66: BEEF | B66: BEEF ANGUS RIBEYE LIP-ON BONE-IN PRIME CERTIFIED_ANGUS_BEEF | C66: CAB | D66: 875146 | E66: 2/15 LB | F66: CS | G66: 19.8799 | H66: per lb | J66: Ruth Family Farms & Ranch to Table
A67: BEEF | B67: BEEF ANGUS RIBEYE LIP-ON BONELESS CHOICE | C67: RUTH FAMILY CHOICE | D67: 882290 | E67: 4/15 LB | F67: CS | G67: 21.5399 | H67: per lb | I67: YES | J67: Purchase History, Ruth Family Farms & Ranch to Table
A68: BEEF | B68: BEEF ANGUS RIBEYE LIP-ON BONELESS PRIME | C68: RUTH FAMILY PRIME | D68: 885344 | E68: 4/15 LB | F68: CS | G68: 23.4599 | H68: per lb | J68: Ruth Family Farms & Ranch to Table
...

Sheet Pork
A1: Pork
A2: Prices as of 09/06/2026 export. Where a product appeared on more than one list with different prices, the highest is shown.
A4: Item Group | B4: Product Description | C4: Brand | D4: Product # | E4: Pack Size | F4: UOM | G4: Price | H4: Price Basis | I4: Price Varies? | J4: Found On These Lists
A5: BACON
A6: BACON | B6: BACON 10-12 SLICED APPLEWOOD SMOKED | C6: NUESKE | D6: 501145 | E6: 2/5 LB | F6: CS | G6: 101.35 | H6: per case | I6: YES | J6: Inventory Plink, Purchase History, S2S Walkin, TCOH S2S
A7: BACON | B7: BACON 14-17 LAYOUT APPLEWOOD DOUBLE SMOKED GAS FLUSHED | C7: RIDGECREST | D7: 649707 | E7: 1/15 LB | F7: CS | G7: 80.23 | H7: per case | I7: YES | J7: Inventory Plink, Purchase History, S2S Walkin, s2s House & Banquets
A8: BACON | B8: BACON 300 COUNT REGULAR SLICED FULLY-COOKED | C8: WEST CREEK | D8: 1039259 | E8: 2/150 CT | F8: CS | G8: 50.13 | H8: per case | J8: Purchase History
A9: BACON | B9: BACON CANADIAN SLICED | C9: ULTIMO | D9: 231729 | E9: 4/2.5 LB | F9: CS | G9: 57.68 | H9: per case | J9: Inventory Plink, S2S Walkin Freezer
A10: BACON | B10: BACON CANADIAN STYLE 0 GRAMS TRANS FAT PER SERVING | C10: HORMEL | D10: 31458 | E10: 2/6 LB | F10: CS | G10: 6.7949 | H10: per lb | J10: s2s House & Banquets
A11: BACON | B11: BACON ITALIAN PANCETTA | C11: VOLPI | D11: 937511 | E11: 2/4 LB | F11: CS | G11: 11.558 | H11: per lb | I11: YES | J11: Inventory Plink, Purchase History, S2S Walkin, TCOH S2S, s2s House & Banquets
A12: BACON | B12: BACON TOPPING 3/8" DICED FULLY-COOKED NATURAL SMOKE ADDED GAS FLUSHED | C12: ROMA | D12: 1007724 | E12: 2/5 LB | F12: CS | G12: 65.29 | H12: per case | J12: S2S Walkin, s2s House & Banquets
A13: BACON | B13: BACON TOPPING 3/8" FULLY-COOKED | C13: ROMA | D13: 175012 | E13: 2/5 LB | F13: CS | G13: 60.83 | H13: per case | J13: Purchase History
A14: CAPICOLA
A15: CAPICOLA | B15: CAPICOLA HOT FULLY-COOKED | C15: VOLPI | D15: 937927 | E15: 2/3 LB | F15: CS | G15: 10.2199 | H15: per lb | I15: YES | J15: Inventory Plink, Purchase History, TCOH S2S, s2s House & Banquets
A16: CAPICOLA | B16: CAPICOLA SLICED | C16: PACKER | D16: 582609 | E16: 6/1 LB | F16: CS | G16: 89.77 | H16: per case | J16: s2s House & Banquets
A17: CASING
A18: CASING | B18: CASING HOG SAUSAGE FRESH | C18: RANAHAN RANCH | D18: 268192 | E18: 1/3 LB | F18: CS | G18: 43.46 | H18: per case | I18: YES | J18: Inventory Plink, Purchase History, S2S Walkin, TCOH S2S
A19: FAT CAUL
A20: FAT CAUL | B20: FAT CAUL PORK FROZEN USE TO WRAP MEAT OR USE FOR BAKING PORK | C20: BROADLEAF | D20: 324161 | E20: 1/10 LB | F20: CS | G20: 7.8099 | H20: per lb | J20: TCOH S2S
A21: FRANKS
A22: FRANKS | B22: FRANKS 4/1 BEEF FROZEN | C22: NATHANS | D22: 970396 | E22: 1/10 LB | F22: CS | G22: 58.06 | H22: per case | I22: YES | J22: Inventory Plink, Purchase History, S2S Walkin, S2S Walkin Freezer, TCOH S2S, s2s House & Banquets
A23: FRANKS | B23: FRANKS 5/1 BEEF BLACK ANGUS 6" FROZEN CRYOVAC GAS FLUSH | C23: RIDGECREST | D23: 879940 | E23: 2/5 LB | F23: CS | G23: 71.88 | H23: per case | J23: Inventory Plink, TCOH S2S
A24: FRANKS | B24: FRANKS 5/1 BEEF FROZEN 0 GRAMS TRANS FAT PER SERVING | C24: NATHANS | D24: 961344 | E24: 50/3.2 OZ | F24: CS | G24: 57.75 | H24: per case | J24: s2s House & Banquets
A25: FRANKS | B25: FRANKS 6/1 BEEF 0 GRAMS TRANS FAT PER SERVING FROZEN | C25: VIENNA | D25: 987807 | E25: 1/10 LB | F25: CS | G25: 80.18 | H25: per case | I25: YES | J25: Purchase History, S2S Basement Freezer, s2s House & Banquets
A26: FRANKS | B26: FRANKS 6/1 BEEF 6" GLUTEN_FREE FROZEN CRYOVAC GAS FLUSH | C26: WEST CREEK | D26: 999658 | E26: 2/5 LB | F26: CS | G26: 61.4 | H26: per case | J26: Inventory Plink, TCOH S2S
A27: FRANKS | B27: FRANKS 8/1 BEEF 6" GLUTEN_FREE FROZEN CRYOVAC GAS FLUSH | C27: WEST CREEK | D27: 157492 | E27: 2/5 LB | F27: CS | G27: 69.35 | H27: per case | J27: Inventory Plink, TCOH S2S
A28: HAM
A29: HAM | B29: HAM CARVING NATURAL JUICE BONELESS APPLEWOOD SMOKED | C29: RIDGECREST | D29: 189728 | E29: 2/7.5 LB | F29: CS | G29: 3.8699 | H29: per lb | J29: s2s House & Banquets
A30: HAM | B30: HAM ENDLESS CURE 81 | C30: HORMEL | D30: 57451 | E30: 1/10.47 LB | F30: CS | G30: 5.6666 | H30: per lb | I30: YES | J30: Inventory Plink, Purchase History, S2S Walkin, TCOH S2S, s2s House & Banquets
A31: HAM | B31: HAM PIT 1 PIECE BOX | C31: MIDDENDORF | D31: 903608 | E31: 1/11-13 LB | F31: CS | G31: 4.1913 | H31: per lb | J31: s2s House & Banquets
A32: HAM | B32: HAM SHANK SMOKED WHOLE FROZEN SEVEN TO 8" LENGTH | C32: PACKER | D32: 967404 | E32: 1/30 LB | F32: CS | G32: 3.2499 | H32: per lb | J32: Inventory Plink, TCOH S2S
A33: HAM | B33: HAM SMOKED SLICED | C33: WEST CREEK | D33: 211771 | E33: 4/2.5 LB | F33: CS | G33: 63.02 | H33: per case | I33: YES | J33: Purchase History, s2s House & Banquets
A34: HAM | B34: HAM SPIRAL BONE-IN HALF W/GLAZE PACK | C34: CURE 81 | D34: 861159 | E34: 1/7.8 LB | F34: CS | G34: 3.8799 | H34: per lb | J34: Inventory Plink, TCOH S2S
A35: HAM | B35: HAM SUGAR CURED BONE-IN SMOKED FROZEN | C35: BURGERS SMOKEHOUSE | D35: 1011022 | E35: 2/17-19 LB | F35: CS | G35: 3.6099 | H35: per lb | J35: s2s House & Banquets
A36: MORTADELLA
A37: MORTADELLA | B37: MORTADELLA LARGE CUT FULLY-COOKED VACUUM-PACKED 0 GRAMS TRANS FAT PER SERVING | C37: VOLPI | D37: 472687 | E37: 2/6 LB | F37: CS | G37: 6.8117 | H37: per lb | J37: Purchase History, s2s House & Banquets
A38: PEPPERONI
A39: PEPPERONI | B39: PEPPERONI GRANDE FROZEN | C39: HORMEL | D39: 328046 | E39: 2/4.88 LB | F39: CS | G39: 5.6358 | H39: per lb | J39: S2S Walkin, s2s House & Banquets
A40: PEPPERONI | B40: PEPPERONI SLICED 16 COUNT CUP N CHAR FROZEN EDIBLE CASING SMALL DIAMETER | C40: ROMA | D40: 268857 | E40: 1/10 LB | F40: CS | G40: 61.99 | H40: per case | I40: YES | J40: Inventory Plink, Purchase History, S2S Basement Freezer, s2s House & Banquets
A41: PORK
...

Sheet Poultry
A1: Poultry
A2: Prices as of 09/06/2026 export. Where a product appeared on more than one list with different prices, the highest is shown.
A4: Item Group | B4: Product Description | C4: Brand | D4: Product # | E4: Pack Size | F4: UOM | G4: Price | H4: Price Basis | I4: Price Varies? | J4: Found On These Lists
A5: CHICKEN
A6: CHICKEN | B6: CHICKEN BREAST 6 OUNCE BONELESS_SKINLESS SINGLE CONTROLLED_VACUUM_PACKED NATURAL FALL | C6: WEST CREEK | D6: 158773 | E6: 2/10 LB | F6: CS | G6: 92.15 | H6: per case | I6: YES | J6: Inventory Plink, Purchase History, TCOH S2S, s2s House & Banquets
A7: CHICKEN | B7: CHICKEN BREAST CHUNK BONELESS WING BREADED FROZEN READY-TO-COOK 100-175 COUNT FRITTER 0 GRAMS TRANS FAT PER SERVING | C7: WEST CREEK | D7: 600752 | E7: 2/5 LB | F7: CS | G7: 37.84 | H7: per case | J7: Inventory Plink, TCOH S2S
A8: CHICKEN | B8: CHICKEN BREAST FILLET BREADED FULLY-COOKED FROZEN NO ANTIBIOTIC EVER | C8: BRAKEBUSH | D8: 243937 | E8: 40/4 OZ | F8: CS | G8: 46.41 | H8: per case | J8: s2s House & Banquets
A9: CHICKEN | B9: CHICKEN BREAST FIVE OUNCE BONELESS_SKINLESS SINGLE CONTROLLED_VACUUM_PACKED NATURAL FALL | C9: WEST CREEK | D9: 158772 | E9: 2/10 LB | F9: CS | G9: 76.75 | H9: per case | J9: Inventory Plink, TCOH S2S
A10: CHICKEN | B10: CHICKEN BREAST PATTY BREADED FULLY-COOKED CHILD_NUTRITION FROZEN WHOLE GRAIN | C10: BRAKEBUSH | D10: 387382 | E10: 51/3.15 OZ | F10: CS | G10: 42.11 | H10: per case | J10: Purchase History
A11: CHICKEN | B11: CHICKEN BREAST RANDOM JUMBO BONELESS_SKINLESS CONTROLLED_VACUUM_PACKED 14 OUNCE AND UP | C11: WEST CREEK | D11: 158753 | E11: 4/10 LB | F11: CS | G11: 65.81 | H11: per case | J11: s2s House & Banquets
A12: CHICKEN | B12: CHICKEN BREAST RANDOM JUMBO BONELESS_SKINLESS CONTROLLED_VACUUM_PACKED ALL NATURAL | C12: WEST CREEK | D12: 887551 | E12: 4/10 LB | F12: CS | G12: 60.24 | H12: per case | I12: YES | J12: Inventory Plink, Purchase History, S2S Walkin, TCOH S2S, s2s House & Banquets
A13: CHICKEN | B13: CHICKEN BREAST SINGLE BONELESS_SKINLESS EIGHT OUNCE SUPER_TRIM | C13: WEST CREEK | D13: 642966 | E13: 2/10 LB | F13: CS | G13: 90.61 | H13: per case | J13: Purchase History
A14: CHICKEN | B14: CHICKEN BREAST SINGLE BONELESS_SKINLESS MARINATED READY-TO-COOK INDIVIDUALLY_FROZEN 15% | C14: WEST CREEK | D14: 886779 | E14: 48/6 OZ | F14: CS | G14: 72.55 | H14: per case | J14: Inventory Plink, TCOH S2S
A15: CHICKEN | B15: CHICKEN BREAST SINGLE BONELESS_SKINLESS READY-TO-COOK INDIVIDUALLY_FROZEN FROZEN | C15: WEST CREEK | D15: 886802 | E15: 48/5 OZ | F15: CS | G15: 63.72 | H15: per case | J15: Inventory Plink, TCOH S2S
A16: CHICKEN | B16: CHICKEN BREAST STRIP FAJITA FULLY-COOKED FROZEN FLAME BROILED | C16: CONTIGO | D16: 529380 | E16: 2/5 LB | F16: CS | G16: 59.45 | H16: per case | I16: YES | J16: Inventory Plink, Purchase History, S2S Walkin, S2S Walkin Freezer, TCOH S2S
A17: CHICKEN | B17: CHICKEN BREAST W/WING AIRLINE INDIVIDUALLY_QUICK_FROZEN BONELESS_SKINON RIB MEAT AND DRUMETTE ANTIBIOTIC_FREE | C17: HARVESTLAND | D17: 335548 | E17: 2/5 LB | F17: CS | G17: 58.71 | H17: per case | I17: YES | J17: Inventory Plink, Purchase History, S2S Walkin, TCOH S2S, s2s House & Banquets
A18: CHICKEN | B18: CHICKEN EIGHT PIECE CONTROLLED_VACUUM_PACKED EIGHT BAGS OF TWO HEAD 2.75-3 LB | C18: WEST CREEK | D18: 158781 | E18: 16/3 LB | F18: CS | G18: 2.0399 | H18: per lb | I18: YES | J18: Inventory Plink, Purchase History, S2S Walkin, TCOH S2S
A19: CHICKEN | B19: CHICKEN LEG QUARTERS JUMBO CONTROLLED_VACUUM_PACKED | C19: WEST CREEK | D19: 210785 | E19: 1/40 LB | F19: CS | G19: 36.32 | H19: per case | J19: Inventory Plink, TCOH S2S
A20: CHICKEN | B20: CHICKEN NUGGET DINOSAUR BREADED FULLY-COOKED FROZEN | C20: PERDUE | D20: 939032 | E20: 2/5 LB | F20: CS | G20: 40.98 | H20: per case | J20: Inventory Plink, Purchase History, S2S Walkin Freezer, TCOH S2S
A21: CHICKEN | B21: CHICKEN SPLIT CONTROLLED_VACUUM_PACKED EIGHT BAGS OF TWO HEAD 2.75-3 LB | C21: WEST CREEK | D21: 158786 | E21: 16/3 LB | F21: CS | G21: 2.1415 | H21: per lb | I21: YES | J21: Inventory Plink, Purchase History, TCOH S2S, s2s House & Banquets
A22: CHICKEN | B22: CHICKEN TENDERLOIN BREADED CAFE READY-TO-COOK FROZEN 70-90 COUNT BARREL CAFE BREADED STYLE FRITTER | C22: WEST CREEK | D22: 600749 | E22: 2/5 LB | F22: CS | G22: 45.94 | H22: per case | I22: YES | J22: Inventory Plink, Purchase History, S2S Walkin Freezer, TCOH S2S, s2s House & Banquets
A23: CHICKEN | B23: CHICKEN THIGH BONE-IN CONTROLLED_VACUUM_PACKED | C23: SANDERSON FARM | D23: 131237 | E23: 1/40 LB | F23: CS | G23: 50.51 | H23: per case | J23: Purchase History
A24: CHICKEN | B24: CHICKEN THIGH BONELESS CHIPOTLE MARINATED | C24: RANAHAN RANCH | D24: 624232 | E24: 2/5 LB | F24: CS | G24: 7.1299 | H24: per lb | I24: YES | J24: Inventory Plink, Purchase History, S2S Walkin, TCOH S2S, s2s House & Banquets
A25: CHICKEN | B25: CHICKEN THIGH FILLET FIVE OUNCE BONELESS FROZEN SKIN-ON | C25: TYSON | D25: 439919 | E25: 4/5 LB | F25: CS | G25: 72.06 | H25: per case | J25: Inventory Plink, TCOH S2S
A26: CHICKEN | B26: CHICKEN THIGH MEAT JERK MARINATED FROZEN | C26: RANAHAN RANCH | D26: 180454 | E26: 4/5 LB | F26: CS | G26: 6.1699 | H26: per lb | J26: s2s House & Banquets
A27: CHICKEN | B27: CHICKEN THIGH MEAT RANDOM BONELESS_SKINLESS CONTROLLED_VACUUM_PACKED ALL NATURAL | C27: WEST CREEK | D27: 158758 | E27: 4/10 LB | F27: CS | G27: 114.44 | H27: per case | I27: YES | J27: Inventory Plink, Purchase History, S2S Walkin, TCOH S2S, s2s House & Banquets
A28: CHICKEN | B28: CHICKEN WING 1ST AND 2ND JUMBO CONTROLLED_VACUUM_PACKED TARGET 4-7 COUNT AVERAGE ALL NATURAL | C28: WEST CREEK | D28: 887550 | E28: 4/10 LB | F28: CS | G28: 72.65 | H28: per case | I28: YES | J28: Inventory Plink, Purchase History, S2S Walkin, TCOH S2S, s2s House & Banquets
A29: DUCK
A30: DUCK | B30: DUCK BREAST 4.5-6.5 OUNCE BONELESS FROZEN | C30: MAPLE LEAF FARM | D30: 683184 | E30: 32/5.5 OZ | F30: CS | G30: 14.7099 | H30: per lb | J30: Inventory Plink, TCOH S2S
A31: DUCK | B31: DUCK BREAST 6.7-8.6 BONELESS FROZEN | C31: MAPLE LEAF FARM | D31: 683185 | E31: 12/2 CT | F31: CS | G31: 16.2599 | H31: per lb | I31: YES | J31: DOWNSTAIRS FREEZER S2S, Inventory Plink, Purchase History, S2S Walkin, TCOH S2S
A32: QUAIL
A33: QUAIL | B33: QUAIL SEMI BONELESS EUROPEAN STYLE FROZEN | C33: MANCHESTER FARMS | D33: 967952 | E33: 24/4-5 OZ | F33: CS | G33: 102.4 | H33: per case | J33: Inventory Plink, S2S Basement Freezer, TCOH S2S
A34: TURKEY
A35: TURKEY | B35: TURKEY BREAST BONELESS_SKINON COOK_IN_BAG FROZEN 10% MARINATED 0 GRAMS TRANS FAT PER SERVING GLUTEN_FREE | C35: BUTTERBALL(MEATS) | D35: 400887 | E35: 6/4.75 LB | F35: CS | G35: 5.4199 | H35: per lb | J35: Inventory Plink, TCOH S2S
A36: TURKEY | B36: TURKEY BREAST FRENCH CUT FROZEN ROTISSERIE | C36: CAROLINA TURKEY | D36: 896744 | E36: 4/7 LB | F36: CS | G36: 5.4199 | H36: per lb | I36: YES | J36: Inventory Plink, Purchase History, S2S Basement Freezer, TCOH S2S
A37: TURKEY | B37: TURKEY BREAST OVEN_ROASTED SKINLESS 2-3 PIECE FULLY-COOKED DOME SHAPED | C37: RIDGECREST | D37: 891769 | E37: 2/9 LB | F37: CS | G37: 5.7799 | H37: per lb | J37: Inventory Plink, TCOH S2S
A38: TURKEY | B38: TURKEY BREAST OVEN_ROASTED SMOKED SKIN-ON 2-3 PIECE FULL-SIZE NATURAL SKIN DOME SHAPE | C38: RIDGECREST | D38: 891766 | E38: 2/9 LB | F38: CS | G38: 6.2999 | H38: per lb | I38: YES | J38: Inventory Plink, Purchase History, S2S Walkin, TCOH S2S, s2s House & Banquets
A39: TURKEY | B39: TURKEY BREAST SMOKED SKINLESS 2-3 PIECE FULLY-COOKED SINGLE BINDER | C39: WEST CREEK | D39: 891751 | E39: 2/9 LB | F39: CS | G39: 5.9299 | H39: per lb | J39: Inventory Plink, TCOH S2S
A40: TURKEY | B40: TURKEY BREAST SMOKED SLICED THREE SLICES PER TWO OUNCE SERVING | C40: WEST CREEK | D40: 211773 | E40: 4/2.5 LB | F40: CS | G40: 77.24 | H40: per case | I40: YES | J40: Purchase History, s2s House & Banquets

Sheet Other Meat
A1: Other Meat
A2: Prices as of 09/06/2026 export. Where a product appeared on more than one list with different prices, the highest is shown.
A4: Item Group | B4: Product Description | C4: Brand | D4: Product # | E4: Pack Size | F4: UOM | G4: Price | H4: Price Basis | I4: Price Varies? | J4: Found On These Lists
A5: ALLIGATOR
A6: ALLIGATOR | B6: ALLIGATOR MEAT FROZEN | C6: PACKER | D6: 66152 | E6: 12/1 LB | F6: CS | G6: 160.66 | H6: per case | J6: Seafood Stocked
A7: BISON
A8: BISON | B8: BISON STRIP LOIN FROZEN | C8: BROADLEAF | D8: 142162 | E8: 1/10 LB | F8: CS | G8: 28.9599 | H8: per lb | J8: s2s House & Banquets
A9: LAMB
A10: LAMB | B10: LAMB GROUND 80/20 FROZEN | C10: PIANCONE EPICUREO | D10: 549693 | E10: 5/2 LB | F10: CS | G10: 117.77 | H10: per case | J10: Inventory Plink, S2S Basement Freezer, S2S Walkin Freezer, TCOH S2S
A11: LAMB | B11: LAMB LEG CHOICE BONELESS BONED_ROLLED_TIED FROZEN | C11: MIDDENDORF | D11: 1035274 | E11: 1/4-6 LB | F11: CS | G11: 16.5016 | H11: per lb | J11: Purchase History
A12: LAMB | B12: LAMB PATTY 3/1 GROUND ROUND FROZEN | C12: SUPERIOR FARMS | D12: 414799 | E12: 1/10 LB | F12: CS | G12: 8.4899 | H12: per lb | J12: Inventory Plink, TCOH S2S
A13: MEATBALL
A14: MEATBALL | B14: MEATBALL BEEF AND PORK GOURMET 1 OUNCE FULLY-COOKED OVEN BAKED 0 GRAMS TRANS FAT PER SERVING | C14: ROMA | D14: 375702 | E14: 2/5 LB | F14: CS | G14: 52.1 | H14: per case | J14: Purchase History
A15: MEATBALL | B15: MEATBALL BEEF AND PORK GOURMET TWO OUNCE FULLY-COOKED OVEN BAKED 0 GRAMS TRANS FAT PER SERVING | C15: ROMA | D15: 375703 | E15: 2/5 LB | F15: CS | G15: 51.24 | H15: per case | J15: Inventory Plink, S2S Basement Freezer, TCOH S2S, s2s House & Banquets
A16: MEATBALL | B16: MEATBALL ITALIAN 1.5 FULLY-COOKED FROZEN | C16: FONTANINI | D16: 856448 | E16: 2/5 LB | F16: CS | G16: 63.98 | H16: per case | J16: s2s House & Banquets
A17: RABBIT
A18: RABBIT | B18: RABBIT WHOLE FRYER 2.5 TO THREE LB FROZEN | C18: PEL-FREEZ | D18: 329242 | E18: 6/1 CT | F18: CS | G18: 16.0399 | H18: per lb | J18: Inventory Plink, TCOH S2S
A19: VEAL
A20: VEAL | B20: VEAL BONES MIXED CUT FROZEN | C20: CATELLI BROS | D20: 874482 | E20: 1/50 LB | F20: CS | G20: 169.45 | H20: per case | J20: Inventory Plink, S2S Walkin, S2S Walkin Freezer, TCOH S2S, s2s House & Banquets
A21: VEAL | B21: VEAL GROUND 80/20 FROZEN | C21: CATELLI BROS | D21: 426407 | E21: 5/2 LB | F21: CS | G21: 89.94 | H21: per case | J21: Purchase History

Sheet Seafood
A1: Seafood
A2: Prices as of 09/06/2026 export. Where a product appeared on more than one list with different prices, the highest is shown.
A4: Item Group | B4: Product Description | C4: Brand | D4: Product # | E4: Pack Size | F4: UOM | G4: Price | H4: Price Basis | I4: Price Varies? | J4: Found On These Lists
A5: ANCHOVY
A6: ANCHOVY | B6: ANCHOVY FLAT FILLET IN OLIVE OIL SPAIN AND PERU | C6: ROMA | D6: 288568 | E6: 12/13 OZ | F6: CS | G6: 132.09 | H6: per case | J6: Purchase History
A7: BARRAMUNDI
A8: BARRAMUNDI | B8: BARRAMUNDI FILLET 8-10 OUNCE BONELESS_SKINLESS FROZEN | C8: PACKER | D8: 599432 | E8: 1/10 LB | F8: CS | G8: 92.11 | H8: per case | J8: Seafood Stocked
A9: CALAMARI
A10: CALAMARI | B10: CALAMARI RING BREADED FROZEN 0 GRAMS TRANS FAT PER SERVING 70 AVERAGE PER LB | C10: TAMPA MAID | D10: 1862 | E10: 6/2 LB | F10: CS | G10: 148.99 | H10: per case | J10: S2S Walkin Freezer, Seafood Stocked
A11: CATFISH
A12: CATFISH | B12: CATFISH FILLET 5-7OZ INDIVIDUALLY_QUICK_FROZEN | C12: PRIDE OF THE POND | D12: 1023637 | E12: 1/15 LB | F12: CS | G12: 111.08 | H12: per case | J12: Purchase History
A13: CATFISH | B13: CATFISH FILLET FOUR OUNCE BREADED DOMESTIC FROZEN | C13: AMERICA'S CATCH | D13: 66954 | E13: 1/10 LB | F13: CS | G13: 83.1 | H13: per case | J13: Seafood Stocked
A14: CATFISH | B14: CATFISH NUGGET TWO OUNCE BREADED DOMESTIC FROZEN | C14: AMERICA'S CATCH | D14: 66955 | E14: 1/10 LB | F14: CS | G14: 41.89 | H14: per case | J14: Seafood Stocked
A15: CATFISH | B15: CATFISH NUGGET UNBREADED DOMESTIC INDIVIDUALLY_QUICK_FROZEN | C15: AMERICA'S CATCH | D15: 371600 | E15: 1/15 LB | F15: CS | G15: 54.13 | H15: per case | J15: Seafood Stocked
A16: CATFISH | B16: CATFISH SHANK FILLET 5-7 OUNCE BONELESS_SKINLESS FROZEN CHINA FARM | C16: WORLD DOCK | D16: 568762 | E16: 1/15 LB | F16: CS | G16: 87.06 | H16: per case | J16: Seafood Stocked
A17: CATFISH | B17: CATFISH SHANK FILLET 5-7 OUNCE CHINA_ABBREV FROZEN CHINA | C17: BEAVER STREET | D17: 894599 | E17: 1/15 LB | F17: CS | G17: 81.76 | H17: per case | J17: Seafood Stocked
A18: CATFISH | B18: CATFISH WHOLE 11-13 OUNCE DOMESTIC INDIVIDUALLY_QUICK_FROZEN | C18: AMERICA'S CATCH | D18: 891435 | E18: 1/15 LB | F18: CS | G18: 84.48 | H18: per case | J18: Seafood Stocked
A19: CATFISH | B19: CATFISH WHOLE 15-17 OUNCE DOMESTIC FROZEN | C19: AMERICA'S CATCH | D19: 939670 | E19: 1/15 LB | F19: CS | G19: 83.53 | H19: per case | J19: Seafood Stocked
A20: CLAM
A21: CLAM | B21: CLAM 11-16 WHITE WHOLE FULLY-COOKED VACUUM-PACKED FROZEN WILD CAUGHT PRODUCT OF VIETNAM | C21: EMPIRES TREASURE | D21: 859740 | E21: 10/1 LB | F21: CS | G21: 47.08 | H21: per case | J21: Seafood Stocked
A22: CLAM | B22: CLAM MEAT BABY W/JUICE FROZEN 0 GRAMS TRANS FAT PER SERVING 300-500 COUNT PER LB | C22: PANAPESCA | D22: 78297 | E22: 10/1 LB | F22: CS | G22: 53.94 | H22: per case | J22: Seafood Stocked
A23: CLAM | B23: CLAM STRIP BREADED FROZEN | C23: SEA BEST | D23: 688884 | E23: 6/1 LB | F23: CS | G23: 42.37 | H23: per case | J23: Seafood Stocked
A24: CLAM | B24: CLAM STRIPS NATURAL BREADED FROZEN | C24: SEA BEST | D24: 603572 | E24: 24/0.25 LB | F24: CS | G24: 44.26 | H24: per case | J24: Seafood Stocked
A25: COD
A26: COD | B26: COD 1-2 COUNT BONELESS_SKINLESS CELLO WRAPPED FROZEN | C26: ICELANDIC | D26: 868050 | E26: 1/5 LB | F26: CS | G26: 73.45 | H26: per case | J26: Seafood Stocked
A27: COD | B27: COD FILLET 16-32 OUNCE BONELESS_SKINLESS FROZEN WILD CAUGHT | C27: WORLD DOCK | D27: 619463 | E27: 1/20 LB | F27: CS | G27: 182.01 | H27: per case | J27: Seafood Stocked
A28: COD | B28: COD FILLET 4.75 OUNCE COUNTRY FRY FROZEN | C28: FPI-FISHERY PRODCTS | D28: 40543 | E28: 2/5 LB | F28: CS | G28: 124.05 | H28: per case | J28: Seafood Stocked
A29: COD | B29: COD FILLET BONELESS_SKINLESS CELLO WRAPPED FROZEN | C29: ICELANDIC | D29: 22255 | E29: 10/5 LB | F29: CS | G29: 694.11 | H29: per case | J29: Seafood Stocked
A30: COD | B30: COD FILLET EIGHT OUNCE BATTERED NEW ENGLISH DOMESTIC FROZEN UNITED_STATES_OF_AMERICA WILD BIG BOB BELLY BUSTER | C30: ICELANDIC | D30: 26066 | E30: 1/10 LB | F30: CS | G30: 124.43 | H30: per case | J30: Seafood Stocked
A31: COD | B31: COD FILLET FOUR OUNCE BATTERED GUINNESS FROZEN WILD | C31: ICELANDIC | D31: 421422 | E31: 1/10 LB | F31: CS | G31: 135.49 | H31: per case | I31: YES | J31: Purchase History, Seafood Stocked
A32: COD | B32: COD FILLET THREE OUNCE BEER_BATTERED SHIPYARD FROZEN | C32: EMPIRES TREASURE | D32: 580945 | E32: 1/10 LB | F32: CS | G32: 127.34 | H32: per case | I32: YES | J32: DOWNSTAIRS FREEZER S2S, Purchase History, Seafood Stocked
A33: COD | B33: COD FILLET TWO OUNCE BEER_BATTERED SHIPYARD FROZEN | C33: EMPIRES TREASURE | D33: 580942 | E33: 1/10 LB | F33: CS | G33: 121.05 | H33: per case | J33: Seafood Stocked
A34: COD | B34: COD LOIN 5OZ INDIVIDUALLY_QUICK_FROZEN CHINA_ABBREV WILD CAUGHT PRODUCT PROCESSED IN CHINA | C34: WORLD DOCK | D34: 405216 | E34: 1/10 LB | F34: CS | G34: 86.46 | H34: per case | J34: Seafood Stocked
A35: COD | B35: COD LOIN 6OZ INDIVIDUALLY_QUICK_FROZEN CHINA (COUNTRY) WILD CAUGHT PRODUCT PROCESSED IN CHINA | C35: WORLD DOCK | D35: 405217 | E35: 1/10 LB | F35: CS | G35: 86.66 | H35: per case | J35: Seafood Stocked
A36: COD | B36: COD LOIN EIGHT OUNCE BONELESS_SKINLESS UNBREADED FROZEN | C36: HIGH LINER | D36: 900331 | E36: 1/10 LB | F36: CS | G36: 123.91 | H36: per case | J36: Seafood Stocked
A37: COD | B37: COD LOIN FOUR OUNCE INDIVIDUALLY_QUICK_FROZEN CHINA_ABBREV WILD CAUGHT PRODUCT PROCESSED IN CHINA | C37: WORLD DOCK | D37: 405215 | E37: 1/10 LB | F37: CS | G37: 97.79 | H37: per case | J37: Seafood Stocked
A38: COD | B38: COD LOIN FOUR OUNCE PREMIUM NATURAL FROZEN 0 GRAMS TRANS FAT PER SERVING | C38: HIGH LINER FDSVC | D38: 76447 | E38: 1/10 LB | F38: CS | G38: 110.72 | H38: per case | J38: Seafood Stocked
A39: COD | B39: COD MINCED THREE OUNCE OVEN READY FROZEN | C39: HIGH LINER FDSVC | D39: 936463 | E39: 2/5 LB | F39: CS | G39: 40.87 | H39: per case | J39: Seafood Stocked
A40: COD | B40: COD NUGGET 1 OUNCE BREADED FROZEN CRISPY FULLY PREPARED WILD UNITED_STATES_OF_AMERICA | C40: HIGH LINER FDSVC | D40: 60198 | E40: 1/10 LB | F40: CS | G40: 121.42 | H40: per case | J40: Seafood Stocked
A41: COD | B41: COD PORTION 3.5-4.5 OUNCE BONELESS_SKINLESS BIAS CUT INDIVIDUALLY_QUICK_FROZEN UNITED_STATES_OF_AMERICA WILD | C41: EMPIRES TREASURE | D41: 589586 | E41: 1/10 LB | F41: CS | G41: 142.5 | H41: per case | J41: Seafood Stocked
...

Sheet Dairy & Eggs
A1: Dairy & Eggs
A2: Prices as of 09/06/2026 export. Where a product appeared on more than one list with different prices, the highest is shown.
A4: Item Group | B4: Product Description | C4: Brand | D4: Product # | E4: Pack Size | F4: UOM | G4: Price | H4: Price Basis | I4: Price Varies? | J4: Found On These Lists
A5: BUTTER
A6: BUTTER | B6: BUTTER SOLIDS UNSALTED AA 0 GRAMS TRANS FAT PER SERVING UNITED_STATES_DEPT_AGRICULTURE SHIELD | C6: NATURES BEST DAIRY | D6: 157189 | E6: 36/1 LB | F6: CS | G6: 108.64 | H6: per case | J6: Purchase History
A7: BUTTER | B7: BUTTER SOLIDS UNSALTED GRADE B 0 GRAMS TRANS FAT PER SERVING UNSHIELDED | C7: SILVER SOURCE | D7: 262666 | E7: 36/1 LB | F7: CS | G7: 89.85 | H7: per case | J7: Purchase History
A8: BUTTERMILK
A9: BUTTERMILK | B9: BUTTERMILK 1% CONTAINER PLASTIC | C9: PRAIRIE FARMS | D9: 249314 | E9: 9/64 OZ | F9: CS | G9: 29.17 | H9: per case | I9: YES | J9: Inventory Plink, Purchase History, S2S Walkin, TCOH S2S, s2s House & Banquets
A10: CHEESE
A11: CHEESE | B11: CHEESE AMARILLO BLANCO 50/50 CHEDDAR MONTEREY_JACK FINE SHREDDED | C11: CORAZO | D11: 797063 | E11: 4/5 LB | F11: CS | G11: 54.19 | H11: per case | J11: S2S Walkin, s2s House & Banquets
A12: CHEESE | B12: CHEESE AMERICAN WHITE LOAF E-Z MELT | C12: ULTIMELT | D12: 231510 | E12: 6/5 LB | F12: CS | G12: 90.13 | H12: per case | I12: YES | J12: Inventory Plink, Purchase History, S2S Walkin, TCOH S2S, s2s House & Banquets
A13: CHEESE | B13: CHEESE AMERICAN YELLOW 120 SLICE 0 GRAMS TRANS FAT PER SERVING EASY PICK | C13: WEST CREEK | D13: 158718 | E13: 4/5 LB | F13: CS | G13: 57.28 | H13: per case | I13: YES | J13: Inventory Plink, Purchase History, S2S Walkin, TCOH S2S
A14: CHEESE | B14: CHEESE ASIAGO FINE SHREDDED BAG | C14: ROMA | D14: 277099 | E14: 2/5 LB | F14: CS | G14: 43.6 | H14: per case | I14: YES | J14: Inventory Plink, Purchase History, S2S Walkin, TCOH S2S
A15: CHEESE | B15: CHEESE BLUE CRUMBLES GLUTEN_FREE | C15: ROMA | D15: 263721 | E15: 1/5 LB | F15: CS | G15: 22.17 | H15: per case | I15: YES | J15: Inventory Plink, Purchase History, S2S Walkin, TCOH S2S
A16: CHEESE | B16: CHEESE BLUE WHEEL | C16: ROMA | D16: 623451 | E16: 1/7 LB | F16: CS | G16: 3.8799 | H16: per lb | J16: s2s House & Banquets
A17: CHEESE | B17: CHEESE BRIE 60% WHEEL PLAIN DOMESTIC DOUBLE CREME | C17: NATURES BEST DAIRY | D17: 516407 | E17: 2/2 LB | F17: CS | G17: 32.9 | H17: per case | I17: YES | J17: Inventory Plink, Purchase History, S2S Walkin, TCOH S2S
A18: CHEESE | B18: CHEESE BURRATA TWO OUNCE BALL 6 PACK OF FOUR COUNT TWO OUNCE BALL | C18: BELGIOIOSO CHEESE | D18: 355554 | E18: 6/8 OZ | F18: CS | G18: 23.52 | H18: per case | I18: YES | J18: Inventory Plink, Purchase History, S2S Walkin, TCOH S2S
A19: CHEESE | B19: CHEESE CHEDDAR MILD YELLOW FEATHER SHREDDED | C19: WEST CREEK | D19: 199428 | E19: 1/5 LB | F19: CS | G19: 16.13 | H19: per case | J19: Purchase History
A20: CHEESE | B20: CHEESE CHEDDAR MILD YELLOW SLICE .75 OUNCE 192 SLICE | C20: WEST CREEK | D20: 158820 | E20: 6/1.5 LB | F20: CS | G20: 30.71 | H20: per case | J20: Purchase History
A21: CHEESE | B21: CHEESE CHEDDAR MONTEREY_JACK FANCY SHREDDED 50/50 | C21: WEST CREEK | D21: 158814 | E21: 4/5 LB | F21: CS | G21: 58.84 | H21: per case | J21: Purchase History
A22: CHEESE | B22: CHEESE CHEDDAR SHARP FEATHER SHREDDED YELLOW | C22: WEST CREEK | D22: 158815 | E22: 4/5 LB | F22: CS | G22: 65.49 | H22: per case | J22: Inventory Plink, TCOH S2S
A23: CHEESE | B23: CHEESE CHEDDAR SHARP WHITE BLOCK 0 GRAMS TRANS FAT PER SERVING | C23: LAND O LAKES | D23: 328716 | E23: 1/10 LB | F23: CS | G23: 43.44 | H23: per case | I23: YES | J23: Purchase History, S2S Walkin
A24: CHEESE | B24: CHEESE CHEDDAR YELLOW SHARP SLICED 53CT 0.75 OUNCE SLICE ON SLICE | C24: ALP & DELL | D24: 255885 | E24: 4/2.5 LB | F24: CS | G24: 46.14 | H24: per case | J24: Inventory Plink, S2S Walkin, TCOH S2S, s2s House & Banquets
A25: CHEESE | B25: CHEESE COTIJA GRATED | C25: CONTIGO | D25: 651725 | E25: 5/2 LB | F25: CS | G25: 56.85 | H25: per case | I25: YES | J25: Inventory Plink, Purchase History, TCOH S2S
A26: CHEESE | B26: CHEESE COTTAGE 4% SMALL CURD 0 GRAMS TRANS FAT PER SERVING | C26: NATURES BEST DAIRY | D26: 201098 | E26: 2/5 LB | F26: CS | G26: 28.73 | H26: per case | I26: YES | J26: Inventory Plink, Purchase History, S2S Walkin, TCOH S2S
A27: CHEESE | B27: CHEESE CREAM LOAF | C27: NATURES BEST DAIRY | D27: 999958 | E27: 10/3 LB | F27: CS | G27: 82.67 | H27: per case | I27: YES | J27: Inventory Plink, Purchase History, S2S Walkin, TCOH S2S
A28: CHEESE | B28: CHEESE CUBE VARIETY PACK 3/4" CHEDDAR PEPPERJACK COLBY JACK | C28: NORTHLAND STAR | D28: 1006778 | E28: 4/5 LB | F28: CS | G28: 78.24 | H28: per case | I28: YES | J28: Purchase History, s2s House & Banquets
A29: CHEESE | B29: CHEESE CUBED VARIETY 3/4" 0 GRAMS TRANS FAT PER SERVING CHEDDAR MONTEREY JACK HOT PEPPER | C29: LAND O LAKES | D29: 2873 | E29: 4/5 LB | F29: CS | G29: 79.88 | H29: per case | J29: s2s House & Banquets
A30: CHEESE | B30: CHEESE FETA TUB | C30: CUCINA ANDOLINA | D30: 248257 | E30: 1/8 LB | F30: CS | G30: 29.16 | H30: per case | I30: YES | J30: Inventory Plink, Purchase History, S2S Walkin, TCOH S2S, s2s House & Banquets
A31: CHEESE | B31: CHEESE GOAT CHUB | C31: NATURES BEST DAIRY | D31: 860112 | E31: 2/4 LB | F31: CS | G31: 66.37 | H31: per case | I31: YES | J31: Purchase History, S2S Walkin, s2s House & Banquets
A32: CHEESE | B32: CHEESE GOUDA SMOKED PROCESSED LOG | C32: WEST CREEK | D32: 508726 | E32: 2/6 LB | F32: CS | G32: 6.1299 | H32: per lb | I32: YES | J32: Inventory Plink, Purchase History, S2S Walkin, TCOH S2S, s2s House & Banquets
A33: CHEESE | B33: CHEESE GOURNAY GARLIC AND HERB SPREADABLE FRANCE | C33: BOURSIN | D33: 266191 | E33: 12/5.2 OZ | F33: CS | G33: 53.41 | H33: per case | I33: YES | J33: Inventory Plink, Purchase History, S2S Walkin, TCOH S2S, s2s House & Banquets
A34: CHEESE | B34: CHEESE GRUYERE KING CUT LOAF DOMESTIC ALPINE STYLE CRYOVAC | C34: WEST CREEK | D34: 445387 | E34: 2/7 LB | F34: CS | G34: 11.8399 | H34: per lb | I34: YES | J34: Inventory Plink, Purchase History, S2S Walkin, TCOH S2S
A35: CHEESE | B35: CHEESE HAVARTI SLICE TWIN PACK | C35: GREAT LAKES | D35: 207141 | E35: 6/24 OZ | F35: CS | G35: 39.76 | H35: per case | J35: Purchase History
A36: CHEESE | B36: CHEESE MASCARPONE | C36: ROMA | D36: 232124 | E36: 6/1 LB | F36: CS | G36: 29.11 | H36: per case | I36: YES | J36: Inventory Plink, Purchase History, S2S Walkin, TCOH S2S, s2s House & Banquets
A37: CHEESE | B37: CHEESE MOZZARELLA BURRATA BALL FOUR OUNCE CREAM FILLED FOUR PER CUP | C37: BELGIOIOSO CHEESE | D37: 342939 | E37: 6/1 LB | F37: CS | G37: 39.3 | H37: per case | J37: Inventory Plink, TCOH S2S
A38: CHEESE | B38: CHEESE MOZZARELLA CILIEGINE FRESH 1/3 OUNCE BALL | C38: BELGIOIOSO CHEESE | D38: 950808 | E38: 2/3 LB | F38: CS | G38: 25.56 | H38: per case | J38: Purchase History
A39: CHEESE | B39: CHEESE MOZZARELLA FRESH LOG SLICED 1 OUNCE 16 COUNT | C39: BELGIOIOSO CHEESE | D39: 875678 | E39: 8/1 LB | F39: CS | G39: 34.47 | H39: per case | J39: Inventory Plink, TCOH S2S
A40: CHEESE | B40: CHEESE MOZZARELLA LOW_MOISTURE_PART_SKIM FEATHER SHREDDED CROWN JEWEL PREMIUM PIZZA CHEESE | C40: PIANCONE | D40: 232981 | E40: 6/5 LB | F40: CS | G40: 74.13 | H40: per case | J40: Inventory Plink, TCOH S2S
A41: CHEESE | B41: CHEESE MOZZARELLA PART_SKIM PROVOLONE SHREDDED PREMIUM 50/50 BLEND MADE W/BUFFALO MILK | C41: BACIO | D41: 337771 | E41: 6/5 LB | F41: CS | G41: 103.5 | H41: per case | I41: YES | J41: Inventory Plink, Purchase History, S2S Walkin, TCOH S2S, s2s House & Banquets
...

Sheet Produce
A1: Produce
A2: Prices as of 09/06/2026 export. Where a product appeared on more than one list with different prices, the highest is shown.
A4: Item Group | B4: Product Description | C4: Brand | D4: Product # | E4: Pack Size | F4: UOM | G4: Price | H4: Price Basis | I4: Price Varies? | J4: Found On These Lists
A5: APPLE
A6: APPLE | B6: APPLE FUJI | C6: PACKER | D6: 954868 | E6: 1/100 CT | F6: CS | G6: 67.95 | H6: per case | I6: YES | J6: Inventory Plink, Purchase History, S2S Walkin, TCOH S2S
A7: APPLE | B7: APPLE GALA EXTRA_FANCY | C7: PACKER | D7: 950172 | E7: 1/40 LB | F7: CS | G7: 46.97 | H7: per case | J7: Inventory Plink, TCOH S2S
A8: APPLE | B8: APPLE GRANNY SMITH | C8: PACKER | D8: 951949 | E8: 1/88 CT | F8: CS | G8: 50.12 | H8: per case | J8: Inventory Plink, TCOH S2S
A9: APPLE | B9: APPLE GRANNY SMITH SLICED PEELED INDIVIDUALLY_QUICK_FROZEN | C9: PACKER | D9: 981538 | E9: 1/30 LB | F9: CS | G9: 50.84 | H9: per case | J9: Inventory Plink, S2S Walkin Freezer, TCOH S2S
A10: ARUGULA
A11: ARUGULA | B11: ARUGULA FRESH | C11: PEAK FRESH PRODUCE | D11: 601221 | E11: 2/2 LB | F11: CS | G11: 22.12 | H11: per case | I11: YES | J11: Inventory Plink, Purchase History, S2S Walkin, TCOH S2S
A12: ASPARAGUS
A13: ASPARAGUS | B13: ASPARAGUS LARGE | C13: PACKER | D13: 23086 | E13: 1/11 LB | F13: CS | G13: 76.33 | H13: per case | I13: YES | J13: Inventory Plink, Purchase History, S2S Walkin, TCOH S2S
A14: ASPARAGUS | B14: ASPARAGUS WHITE | C14: PACKER | D14: 953915 | E14: 1/11 LB | F14: CS | G14: 99.24 | H14: per case | J14: TCOH S2S
A15: AVOCADO
A16: AVOCADO | B16: AVOCADO BREAKER | C16: PACKER | D16: 302102 | E16: 1/48 CT | F16: CS | G16: 46.13 | H16: per case | I16: YES | J16: Inventory Plink, Purchase History, S2S Walkin, TCOH S2S
A17: AVOCADO | B17: AVOCADO HASS FRESH | C17: PACKER | D17: 266279 | E17: 1/48 CT | F17: CS | G17: 85.94 | H17: per case | J17: Inventory Plink, TCOH S2S
A18: AVOCADO | B18: AVOCADO PULP CHUNKY FRESH | C18: CONTIGO | D18: 625690 | E18: 8/2 LB | F18: CS | G18: 68.54 | H18: per case | I18: YES | J18: Inventory Plink, Purchase History, S2S Walkin, TCOH S2S, s2s House & Banquets
A19: AVOCADO | B19: AVOCADO PULP CREAMY | C19: CONTIGO | D19: 625692 | E19: 8/2 LB | F19: CS | G19: 75.29 | H19: per case | J19: Purchase History
A20: BANANA
A21: BANANA | B21: BANANA | C21: PREMIUM UNITED | D21: 940705 | E21: 4/10 LB | F21: CS | G21: 35.06 | H21: per case | I21: YES | J21: Inventory Plink, Purchase History, S2S Walkin, TCOH S2S
A22: BANANA | B22: BANANA FRESH | C22: PACKER | D22: 986347 | E22: 1/10 LB | F22: CS | G22: 9.26 | H22: per case | J22: Inventory Plink, S2S Walkin, TCOH S2S
A23: BANANA | B23: BANANA LEAVES | C23: PACKER | D23: 321860 | E23: 1/10 LB | F23: CS | G23: 48.16 | H23: per case | J23: Inventory Plink, TCOH S2S
A24: BASIL
A25: BASIL | B25: BASIL FRESH | C25: PEAK FRESH PRODUCE | D25: 855571 | E25: 1/1 LB | F25: CS | G25: 16.95 | H25: per case | I25: YES | J25: Inventory Plink, Purchase History, S2S Walkin, TCOH S2S, s2s House & Banquets
A26: BEET
A27: BEET | B27: BEET | C27: PACKER | D27: 941831 | E27: 5/5 LB | F27: CS | G27: 28.4 | H27: per case | J27: Purchase History
A28: BERRY
A29: BERRY | B29: BERRY MIXED INDIVIDUALLY_QUICK_FROZEN | C29: WEST CREEK | D29: 619536 | E29: 2/5 LB | F29: CS | G29: 42.98 | H29: per case | J29: S2S Walkin Freezer
A30: BLACKBERRIES
A31: BLACKBERRIES | B31: BLACKBERRIES | C31: PACKER | D31: 61768 | E31: 12/.5 PT | F31: CS | G31: 47.97 | H31: per case | I31: YES | J31: Inventory Plink, Purchase History, S2S Walkin, TCOH S2S
A32: BLACKBERRIES | B32: BLACKBERRIES WHOLE PREMIUM INDIVIDUALLY_QUICK_FROZEN | C32: WYMAN | D32: 874768 | E32: 2/5 LB | F32: CS | G32: 42.22 | H32: per case | I32: YES | J32: Inventory Plink, Purchase History, S2S Walkin Freezer
A33: BLUEBERRIES
A34: BLUEBERRIES | B34: BLUEBERRIES CULTIVATED WHOLE INDIVIDUALLY_QUICK_FROZEN | C34: WEST CREEK | D34: 475345 | E34: 2/5 LB | F34: CS | G34: 43.56 | H34: per case | I34: YES | J34: Inventory Plink, Purchase History, S2S Walkin Freezer
A35: BLUEBERRIES | B35: BLUEBERRIES FRESH | C35: PACKER | D35: 953841 | E35: 1/12 CT | F35: CS | G35: 72.65 | H35: per case | I35: YES | J35: Inventory Plink, Purchase History, S2S Walkin, TCOH S2S, s2s House & Banquets
A36: BOK
A37: BOK | B37: BOK CHOY BABY | C37: PACKER | D37: 953907 | E37: 1/10 LB | F37: CS | G37: 41.74 | H37: per case | J37: Inventory Plink, TCOH S2S
A38: BROCCOLI
A39: BROCCOLI | B39: BROCCOLI BROCCOLINI BABY | C39: PACKER | D39: 367315 | E39: 1/18 CT | F39: CS | G39: 52.9 | H39: per case | J39: Purchase History
A40: BROCCOLI | B40: BROCCOLI CROWN ICELESS | C40: PEAK FRESH PRODUCE | D40: 865025 | E40: 1/20 LB | F40: CS | G40: 56.15 | H40: per case | I40: YES | J40: Inventory Plink, Purchase History, S2S Walkin, TCOH S2S
A41: BROCCOLI | B41: BROCCOLI FLORETS | C41: PEAK FRESH PRODUCE | D41: 880569 | E41: 4/3 LB | F41: CS | G41: 35.83 | H41: per case | I41: YES | J41: Inventory Plink, Purchase History, TCOH S2S
...

Sheet Bakery & Bread
A1: Bakery & Bread
A2: Prices as of 09/06/2026 export. Where a product appeared on more than one list with different prices, the highest is shown.
A4: Item Group | B4: Product Description | C4: Brand | D4: Product # | E4: Pack Size | F4: UOM | G4: Price | H4: Price Basis | I4: Price Varies? | J4: Found On These Lists
A5: BAGEL
A6: BAGEL | B6: BAGEL EVERYTHING 4.5 OUNCE FROZEN | C6: DELANCEY STREET | D6: 1053616 | E6: 1/45 CT | F6: CS | G6: 31.01 | H6: per case | J6: Purchase History
A7: BAGEL | B7: BAGEL PLAIN 4.5 OUNCE FROZEN | C7: DELANCEY STREET | D7: 1053624 | E7: 1/45 CT | F7: CS | G7: 30.15 | H7: per case | J7: DOWNSTAIRS FREEZER S2S, Purchase History
A8: BISCUIT
A9: BISCUIT | B9: BISCUIT BACON EGG CHEESE INDIVIDUALLY_WRAPPED FROZEN 3" 0 GRAMS TRANS FAT PER SERVING | C9: JIMMY DEAN | D9: 989237 | E9: 12/3.6 OZ | F9: CS | G9: 26.37 | H9: per case | J9: Inventory Plink, TCOH S2S
A10: BISCUIT | B10: BISCUIT DOUGH BUTTERMILK 2.25 OUNCE FROZEN READY SPLIT PUCK BULK | C10: HERITAGE OVENS | D10: 433203 | E10: 216/2.25 OZ | F10: CS | G10: 61.79 | H10: per case | I10: YES | J10: DOWNSTAIRS FREEZER S2S, Inventory Plink, Purchase History, S2S Basement Freezer, S2S Walkin Freezer, TCOH S2S
A11: BISCUIT | B11: BISCUIT LADY FINGER ITALIAN 0 GRAMS TRANS FAT PER SERVING | C11: ROLAND | D11: 45204 | E11: 10/60 CT | F11: CS | G11: 86.61 | H11: per case | J11: Inventory Plink, TCOH S2S, s2s Dry Storage
A12: BISCUIT | B12: BISCUIT SAUSAGE EGG CHEESE FROZEN 3" INDIVIDUALLY_WRAPPED 0 GRAMS TRANS FAT PER SERVING | C12: JIMMY DEAN | D12: 989217 | E12: 12/4.9 OZ | F12: CS | G12: 27.32 | H12: per case | J12: Inventory Plink, TCOH S2S
A13: BREAD
A14: BREAD | B14: BREAD BAGUETTE LOAF PARBAKED | C14: COMPANION | D14: 430838 | E14: 20/13 OZ | F14: CS | G14: 49.69 | H14: per case | I14: YES | J14: Inventory Plink, Purchase History, S2S Basement Freezer, TCOH S2S, s2s House & Banquets
A15: BREAD | B15: BREAD BRIOCHE LOAF 12.5 IN SLICED 3/4 FROZEN | C15: ROTELLAS | D15: 533604 | E15: 6/1 CT | F15: CS | G15: 31.33 | H15: per case | J15: DOWNSTAIRS FREEZER S2S, Purchase History
A16: BREAD | B16: BREAD CRUMBS PANKO UNTOASTED JAPANESE STYLE 0 GRAMS TRANS FAT PER SERVING | C16: KIKKOMAN | D16: 948214 | E16: 1/25 LB | F16: CS | G16: 38.94 | H16: per case | J16: s2s Dry Storage
A17: BREAD | B17: BREAD CRUMBS TOASTED PANKO JAPANESE STYLE 0 GRAMS TRANS FAT PER SERVING | C17: KIKKOMAN | D17: 32728 | E17: 1/25 LB | F17: CS | G17: 31.87 | H17: per case | I17: YES | J17: Purchase History, s2s Dry Storage, s2s House & Banquets
A18: BREAD | B18: BREAD MARBLE RYE THICK SLICE 14 SLICES 3/4" | C18: ROTELLAS | D18: 997339 | E18: 6/33 OZ | F18: CS | G18: 43.62 | H18: per case | I18: YES | J18: Inventory Plink, Purchase History, S2S Basement Freezer, TCOH S2S
A19: BREAD | B19: BREAD PITA WHITE 7" | C19: OLYMPIA | D19: 870445 | E19: 120/3.2 OZ | F19: CS | G19: 36.64 | H19: per case | J19: Purchase History
A20: BREAD | B20: BREAD PITA WHITE 7.25" THIN FROZEN 12 PACK OF 10 COUNT | C20: GRECIAN DELIGHT | D20: 519954 | E20: 120/2.8 OZ | F20: CS | G20: 40.64 | H20: per case | J20: Inventory Plink, S2S Basement Freezer, TCOH S2S
A21: BREAD | B21: BREAD PULLMAN WHITE 28 SLICE 0 GRAMS TRANS FAT PER SERVING 4X4" SLICES .47 INCH THICK | C21: HERITAGE OVENS | D21: 857648 | E21: 10/24 OZ | F21: CS | G21: 43.5 | H21: per case | J21: Purchase History
A22: BREAD | B22: BREAD SOUR REUBEN | C22: ROTELLAS | D22: 997338 | E22: 1/6 CT | F22: CS | G22: 38.29 | H22: per case | J22: Inventory Plink, S2S Basement Freezer, TCOH S2S
A23: BREAD | B23: BREAD SOURDOUGH 5/8" OVAL LARGE | C23: ROTELLAS | D23: 981353 | E23: 8/35 OZ | F23: CS | G23: 41.74 | H23: per case | I23: YES | J23: Inventory Plink, Purchase History, TCOH S2S
A24: BREAD | B24: BREAD SOURDOUGH BISTRO SLICED | C24: ACE BAKERY | D24: 989827 | E24: 8/34.9 OZ | F24: CS | G24: 59.06 | H24: per case | J24: DOWNSTAIRS FREEZER S2S, Purchase History
A25: BREAD | B25: BREAD TEXAS TOAST WHITE 15 SLICE 0 GRAMS TRANS FAT PER SERVING | C25: HERITAGE OVENS | D25: 857642 | E25: 10/24 OZ | F25: CS | G25: 39.91 | H25: per case | J25: Inventory Plink, TCOH S2S
A26: BREAD | B26: BREAD WHEAT WHOLE SLICED 9 GRAIN SESAME TOP | C26: ROTELLAS | D26: 228771 | E26: 6/18 SL | F26: CS | G26: 36.94 | H26: per case | J26: Inventory Plink, TCOH S2S
A27: BREAD | B27: BREAD WHEATBERRY THICK 19 SLICE 0 GRAMS TRANS FAT PER SERVING | C27: HERITAGE OVENS | D27: 857644 | E27: 8/36 OZ | F27: CS | G27: 50.53 | H27: per case | I27: YES | J27: DOWNSTAIRS FREEZER S2S, Inventory Plink, Purchase History, S2S Basement Freezer, TCOH S2S
A28: BREADSTICK
A29: BREADSTICK | B29: BREADSTICK GARLIC 8" PARBAKED BULK PACK IN PLASTIC LINER | C29: HERITAGE OVENS | D29: 291103 | E29: 1/126 CT | F29: CS | G29: 53.13 | H29: per case | I29: YES | J29: Inventory Plink, Purchase History, S2S Basement Freezer, TCOH S2S, s2s House & Banquets
A30: BUN
A31: BUN | B31: BUN BRIOCHE 4" | C31: ACE BAKERY | D31: 217412 | E31: 72/2.6 OZ | F31: CS | G31: 54.59 | H31: per case | J31: Purchase History
A32: BUN | B32: BUN BRIOCHE SLICED 4.5" FROZEN | C32: TURANO | D32: 360907 | E32: 8/10 CT | F32: CS | G32: 66.03 | H32: per case | I32: YES | J32: Inventory Plink, Purchase History, S2S Basement Freezer, TCOH S2S
A33: BUN | B33: BUN BURGER 4" BLACK AND WHITE SESAME | C33: ACE BAKERY | D33: 209416 | E33: 72/3.17 OZ | F33: CS | G33: 48.83 | H33: per case | J33: DOWNSTAIRS FREEZER S2S, Purchase History
A34: BUN | B34: BUN GOURMET W/SHINE 4.25" FROZEN | C34: ROTELLAS | D34: 602334 | E34: 5/12 CT | F34: CS | G34: 32.15 | H34: per case | J34: Inventory Plink, TCOH S2S
A35: BUN | B35: BUN HAMBURGER FOUR IN GLUTEN_FREE INDIVIDUALLY_WRAPPED FROZEN | C35: UDIS | D35: 344720 | E35: 24/3.2 OZ | F35: CS | G35: 45.44 | H35: per case | I35: YES | J35: DOWNSTAIRS FREEZER S2S, Inventory Plink, Purchase History, S2S Basement Freezer, TCOH S2S, s2s House & Banquets
A36: BUN | B36: BUN HAMBURGER SLICED 4" 0 GRAMS TRANS FAT PER SERVING FROZEN EIGHT BAG 12 PER BAG | C36: HERITAGE OVENS | D36: 857651 | E36: 96/2.1 OZ | F36: CS | G36: 39.65 | H36: per case | J36: Inventory Plink, S2S Basement Freezer, TCOH S2S
A37: BUN | B37: BUN HAMBURGER WHOLE GRAIN 4" | C37: NATURES OWN | D37: 490708 | E37: 8/12 CT | F37: CS | G37: 26.97 | H37: per case | J37: Inventory Plink, TCOH S2S
A38: BUN | B38: BUN HOT DOG AND BRAT SMALL | C38: ROTELLAS | D38: 336462 | E38: 6/12 CT | F38: CS | G38: 24.76 | H38: per case | J38: Purchase History
A39: BUN | B39: BUN HOT DOG POPPY 6" FROZEN | C39: VIENNA | D39: 958085 | E39: 12/10 CT | F39: CS | G39: 64.56 | H39: per case | I39: YES | J39: DOWNSTAIRS FREEZER S2S, Inventory Plink, Purchase History, S2S Basement Freezer, TCOH S2S, s2s House & Banquets
A40: BUN | B40: BUN HOT DOG SLICED 6 IN 0 GRAMS TRANS FAT PER SERVING EIGHT BAG 12 PER BAG | C40: HERITAGE OVENS | D40: 857650 | E40: 96/1.7 OZ | F40: CS | G40: 38.34 | H40: per case | J40: Inventory Plink, S2S Basement Freezer, TCOH S2S, s2s House & Banquets
A41: BUN | B41: BUN PRETZEL BURGER | C41: KINGS HAWAIIAN | D41: 804611 | E41: 8/4 CT | F41: CS | G41: 28.65 | H41: per case | J41: s2s House & Banquets
...

Sheet Frozen & Prepared Foods
A1: Frozen & Prepared Foods
A2: Prices as of 09/06/2026 export. Where a product appeared on more than one list with different prices, the highest is shown.
A4: Item Group | B4: Product Description | C4: Brand | D4: Product # | E4: Pack Size | F4: UOM | G4: Price | H4: Price Basis | I4: Price Varies? | J4: Found On These Lists
A5: APPETIZER
A6: APPETIZER | B6: APPETIZER BEEF TENDERLOIN ENCROUTE BAKE ONLY | C6: ENTICE CULINARY | D6: 256290 | E6: 4/25 CT | F6: CS | G6: 155.6 | H6: per case | I6: YES | J6: Inventory Plink, Purchase History, S2S Basement Freezer, TCOH S2S, s2s House & Banquets
A7: APPETIZER | B7: APPETIZER CHEDDAR WHITE NUGGET HOMESTYLE BREADED | C7: RIVERSIDE | D7: 438242 | E7: 32/5 OZ | F7: CS | G7: 61.68 | H7: per case | J7: Inventory Plink, TCOH S2S
A8: APPETIZER | B8: APPETIZER CHEESE CURD LIGHTLY BREADED WISCONSIN FROZEN | C8: ENTICE | D8: 616854 | E8: 2/5 LB | F8: CS | G8: 64.99 | H8: per case | I8: YES | J8: Inventory Plink, Purchase History, S2S Basement Freezer, S2S Walkin Freezer, TCOH S2S
A9: APPETIZER | B9: APPETIZER CORN DOG CHICKEN MINI .67 OUNCE FROZEN 0 GRAMS TRANS FAT PER SERVING | C9: FOSTER FARMS | D9: 938447 | E9: 2/5 LB | F9: CS | G9: 41.84 | H9: per case | J9: Inventory Plink, Purchase History, S2S Basement Freezer, S2S Walkin Freezer, TCOH S2S
A10: APPETIZER | B10: APPETIZER EGG ROLL VEGETABLE .75 OUNCE 0 GRAMS TRANS FAT PER SERVING | C10: ENTICE CULINARY | D10: 256285 | E10: 4/25 CT | F10: CS | G10: 76.51 | H10: per case | I10: YES | J10: Purchase History, S2S Basement Freezer, s2s House & Banquets
A11: APPETIZER | B11: APPETIZER FRIED GREEN TOMATO BREADED FROZEN HARVEST CREATIONS | C11: WEST CREEK | D11: 444338 | E11: 6/2 LB | F11: CS | G11: 71.09 | H11: per case | J11: Inventory Plink, S2S Basement Freezer, S2S Walkin Freezer, TCOH S2S, s2s House & Banquets
A12: APPETIZER | B12: APPETIZER MACARONI AND CHEESE BITE | C12: FREDS FOR STARTERS | D12: 142220 | E12: 6/2 LB | F12: CS | G12: 55.65 | H12: per case | J12: Inventory Plink, TCOH S2S
A13: APPETIZER | B13: APPETIZER MUSHROOM BUTTER BREADED 24 40 PER LB | C13: ENTICE | D13: 998658 | E13: 6/2.5 LB | F13: CS | G13: 56.82 | H13: per case | J13: Inventory Plink, TCOH S2S
A14: APPETIZER | B14: APPETIZER MUSHROOM PORTOBELLO BREADED ITALIAN FROZEN | C14: LAKE ERIE FZ | D14: 372118 | E14: 4/2 LB | F14: CS | G14: 41.98 | H14: per case | J14: Inventory Plink, TCOH S2S
A15: APPETIZER | B15: APPETIZER ONION RING BEER_BATTERED 5/8" THICK 13-25 PER LB | C15: ENTICE | D15: 998673 | E15: 6/2.5 LB | F15: CS | G15: 60.16 | H15: per case | I15: YES | J15: Inventory Plink, Purchase History, S2S Walkin Freezer, TCOH S2S
A16: APPETIZER | B16: APPETIZER POPPER JALAPENO CREAM CHEESE 0 GRAMS TRANS FAT PER SERVING 12 -16 PER LB | C16: ENTICE | D16: 998660 | E16: 4/3 LB | F16: CS | G16: 70.61 | H16: per case | J16: Inventory Plink, TCOH S2S
A17: APPETIZER | B17: APPETIZER PORTOBELLO MUSHROOM FRIES BREADED | C17: FREDS FOR STARTERS | D17: 866850 | E17: 6/2 LB | F17: CS | G17: 82.73 | H17: per case | J17: Purchase History
A18: APPETIZER | B18: APPETIZER RAVIOLI BEEF SQUARE BREADED .6 OUNCE | C18: LOUISA | D18: 212692 | E18: 2/5 LB | F18: CS | G18: 35.66 | H18: per case | J18: Inventory Plink, TCOH S2S, s2s House & Banquets
A19: APPETIZER | B19: APPETIZER SCALLOP BACON_WRAPPED 0 GRAMS TRANS FAT PER SERVING PRECOOKED BACON | C19: ENTICE CULINARY | D19: 256278 | E19: 4/25 CT | F19: CS | G19: 138.47 | H19: per case | J19: Inventory Plink, S2S Basement Freezer
A20: APPETIZER | B20: APPETIZER SPANAKOPITA .6 OUNCE 0 GRAMS TRANS FAT PER SERVING BAKE | C20: ENTICE CULINARY | D20: 256284 | E20: 4/25 CT | F20: CS | G20: 93.55 | H20: per case | J20: Inventory Plink, S2S Basement Freezer, S2S Walkin Freezer, TCOH S2S, s2s House & Banquets
A21: APPETIZER | B21: APPETIZER SPRING ROLL PLAIN FROZEN | C21: CUISINE INNOVATIONS | D21: 906801 | E21: 100/1 OZ | F21: CS | G21: 93.01 | H21: per case | J21: Purchase History
A22: FRIES
A23: FRIES | B23: FRIES 3/8 IN REGULAR CUT COATED EXTRA-LONG-FANCY | C23: COLOSSAL CRISP | D23: 982746 | E23: 6/5 LB | F23: CS | G23: 66.62 | H23: per case | J23: Purchase History
A24: FRIES | B24: FRIES 3/8 STRGHT CUT EPIC CRUNCH EXTRA-LONG-FANCY SKINLESS FROZEN | C24: ROMA | D24: 990298 | E24: 6/5 LB | F24: CS | G24: 50.85 | H24: per case | I24: YES | J24: Inventory Plink, Purchase History, S2S Walkin Freezer, TCOH S2S
A25: FRIES | B25: FRIES 3/8" CRINKLE CUT BATTERED HIGHWAY 40 SEASONED | C25: WEST CREEK | D25: 579670 | E25: 6/5 LB | F25: CS | G25: 57.61 | H25: per case | J25: s2s House & Banquets
A26: FRIES | B26: FRIES 5/16 IN CRINKLE CUT THIN FROZEN | C26: STEALTH FRIES | D26: 974820 | E26: 6/5 LB | F26: CS | G26: 73.67 | H26: per case | J26: Purchase History
A27: FRIES | B27: FRIES LATTICE SKIN-ON FROZEN MID TIER FRY ONLY | C27: WEST CREEK | D27: 369832 | E27: 6/4.5 LB | F27: CS | G27: 63.26 | H27: per case | I27: YES | J27: Inventory Plink, Purchase History, TCOH S2S
A28: FRIES | B28: FRIES SPIRAL CUT SEASONED 0 GRAMS TRANS FAT PER SERVING SKIN-ON FRY OR OVEN | C28: WEST CREEK | D28: 197441 | E28: 6/5 LB | F28: CS | G28: 72.63 | H28: per case | I28: YES | J28: Purchase History, s2s House & Banquets
A29: FRIES | B29: FRIES SWEET POTATO 3/8 RIB CUT FROZEN SEASONED 3/8 X 3/4 0 GRAMS TRANS FAT PER SERVING | C29: SWEET THINGS | D29: 316418 | E29: 3/5 LB | F29: CS | G29: 50.42 | H29: per case | J29: Inventory Plink, Purchase History, S2S Walkin Freezer, TCOH S2S
A30: FRIES | B30: FRIES SWEET POTATO THIN CUT 0 GRAMS TRANS FAT PER SERVING 5/16" X 1/4" FRY OR OVEN CLEAR COAT | C30: WEST CREEK | D30: 416703 | E30: 6/2.5 LB | F30: CS | G30: 43.35 | H30: per case | J30: Inventory Plink, TCOH S2S
A31: HASHBROWN
A32: HASHBROWN | B32: HASHBROWN SHREDDED INDIVIDUALLY_QUICK_FROZEN OVEN OR GRILL | C32: WEST CREEK | D32: 197439 | E32: 6/3 LB | F32: CS | G32: 37.25 | H32: per case | J32: Inventory Plink, S2S Basement Freezer, TCOH S2S
A33: MANICOTTI
A34: MANICOTTI | B34: MANICOTTI CHEESE | C34: LOUISA | D34: 959761 | E34: 72/3 OZ | F34: CS | G34: 61.55 | H34: per case | J34: Inventory Plink, TCOH S2S
A35: PIZZA
A36: PIZZA | B36: PIZZA CHEESE 50/50 WHOLE GRAIN 4X6 0 GRAMS TRANS FAT PER SERVING | C36: TONYS | D36: 869643 | E36: 96/4.6 OZ | F36: CS | G36: 80.33 | H36: per case | J36: Purchase History
A37: PIZZA | B37: PIZZA CRUST 14" PARBAKED FROZEN | C37: ULTIMO | D37: 102731 | E37: 10/15 OZ | F37: CS | G37: 21.14 | H37: per case | J37: Inventory Plink, s2s House & Banquets
